Workbook

Sheet regras
B2: net | C2: Até 50MM | D2: 50MM - 100MM | E2: 100MM - 300MM | F2: > 300MM | O2: Até 50MM | P2: 50MM - 100MM | Q2: 100MM - 300MM | R2: > 300MM
B3: cap | C3: x | D3: x | E3: x | F3: x | O3: 200000 | P3: 500000 | Q3: 750000 | R3: 1000000
B4: receita | C4: x | D4: x | E4: x | F4: x | H4: KPIs | I4: GROWING | J4: PLENO | K4: SENIOR | L4: MASTER | N4: REGRA 3/4 | O4: 35000 | P4: 42000 | Q4: 54600 | R4: 76440
B5: tempo de casa | C5: x | D5: x | E5: x | F5: x | H5: Captação | I5: 500000 | J5: 750000 | K5: 1500000 | L5: 2000000 | O5: 2 | P5: 3 | Q5: 4 | R5: 5
C6: GROWING | D6: PLENO | E6: SENIOR | F6: MASTER | H6: Receita | I6: =O4*1.2 -> 42000 | J6: =P4*1.2 -> 50400 | K6: =Q4*1.2 -> 65520 | L6: =R4*1.2 -> 91728 | N6: BASE | O6: GROWING | P6: PLENO | Q6: SENIOR | R6: MASTER
B7: RENDA FIXA | C7: 0.5 | D7: 0.5 | E7: 0.55 | F7: 0.6 | H7: Modelo de Servir | I7: 60 | J7: 60 | K7: 60 | L7: 60 | N7: 0.5 | O7: =N7+$I$15 -> 0.525 | P7: =N7+$J$15 -> 0.55 | Q7: =N7+$K$15 -> 0.575 | R7: =N7+$L$15 -> 0.6
B8: FUNDOS | C8: 0.5 | D8: 0.5 | E8: 0.55 | F8: 0.6 | N8: 0.5 | O8: =N8+$I$15 -> 0.525 | P8: =N8+$J$15 -> 0.55 | Q8: =N8+$K$15 -> 0.575 | R8: =N8+$L$15 -> 0.6
B9: PREV | C9: 0.5 | D9: 0.5 | E9: 0.55 | F9: 0.6 | N9: 0.5 | O9: =N9+$I$15 -> 0.525 | P9: =N9+$J$15 -> 0.55 | Q9: =N9+$K$15 -> 0.575 | R9: =N9+$L$15 -> 0.6
B10: FEE FIXO | C10: 0.5 | D10: 0.5 | E10: 0.55 | F10: 0.55 | N10: 0.5 | O10: =N10+$I$15 -> 0.525 | P10: =N10+$J$15 -> 0.55 | Q10: =N10+$K$15 -> 0.575 | R10: =N10+$L$15 -> 0.6
B11: CAMBIO | C11: 0.5 | D11: 0.5 | E11: 0.55 | F11: 0.55 | H11: BÔNUS | I11: GROWING | J11: PLENO | K11: SENIOR | L11: MASTER | N11: 0.5 | O11: =N11+$I$15 -> 0.525 | P11: =N11+$J$15 -> 0.55 | Q11: =N11+$K$15 -> 0.575 | R11: =N11+$L$15 -> 0.6 | T11: 16000 | U11: =T11*1.05 -> 16800 | V11: =16000*1.075 -> 17200 | W11: =16000*1.1 -> 17600
B12: COE | C12: 0.45 | D12: 0.5 | E12: 0.5 | F12: 0.55 | H12: Captação | I12: 0.01 | J12: 0.02 | K12: 0.03 | L12: 0.04 | N12: 0.45 | O12: =N12+$I$15 -> 0.475 | P12: =N12+$J$15 -> 0.5 | Q12: =N12+$K$15 -> 0.525 | R12: =N12+$L$15 -> 0.55
B13: FIIs | C13: 0.4 | D13: 0.45 | E13: 0.5 | F13: 0.5 | H13: Receita | I13: 0.01 | J13: 0.02 | K13: 0.03 | L13: 0.04 | N13: 0.4 | O13: =N13+$I$15 -> 0.425 | P13: =N13+$J$15 -> 0.45 | Q13: =N13+$K$15 -> 0.475 | R13: =N13+$L$15 -> 0.5
B14: RV | C14: 0.3 | D14: 0.3 | E14: 0.35 | F14: 0.4 | H14: Modelo de Servir | I14: 0.005 | J14: 0.01 | K14: 0.015 | L14: 0.02 | N14: 0.3 | O14: =N14+$I$15 -> 0.325 | P14: =N14+$J$15 -> 0.35 | Q14: =N14+$K$15 -> 0.375 | R14: =N14+$L$15 -> 0.4
B15: INTERNACIONAL | C15: 0.3 | D15: 0.3 | E15: 0.35 | F15: 0.4 | I15: =SUM(I12:I14) -> 0.025 | J15: =SUM(J12:J14) -> 0.05 | K15: =SUM(K12:K14) -> 0.075 | L15: =SUM(L12:L14) -> 0.1 | N15: 0.3 | O15: =N15+$I$15 -> 0.325 | P15: =N15+$J$15 -> 0.35 | Q15: =N15+$K$15 -> 0.375 | R15: =N15+$L$15 -> 0.4
B16: PRODUTOS PJ | C16: 0.3 | D16: 0.3 | E16: 0.33 | F16: 0.35 | N16: 0.3 | O16: =N16+$I$15 -> 0.325 | P16: =N16+$J$15 -> 0.35 | Q16: =N16+$K$15 -> 0.375 | R16: =N16+$L$15 -> 0.4
B17: CONSÓRCIO | C17: 0.3 | D17: 0.3 | E17: 0.33 | F17: 0.35 | N17: 0.3 | O17: =N17+$I$15 -> 0.325 | P17: =N17+$J$15 -> 0.35 | Q17: =N17+$K$15 -> 0.375 | R17: =N17+$L$15 -> 0.4
B18: SEGUROS | C18: 0.3 | D18: 0.3 | E18: 0.33 | F18: 0.35 | N18: 0.3 | O18: =N18+$I$15 -> 0.325 | P18: =N18+$J$15 -> 0.35 | Q18: =N18+$K$15 -> 0.375 | R18: =N18+$L$15 -> 0.4
B19: PRECATÓRIO | C19: 0.2 | D19: 0.2 | E19: 0.2 | F19: 0.2 | H19: PTNSHIP | I19: GROWING | J19: PLENO | K19: SENIOR | L19: MASTER | N19: 0.2 | O19: =N19+$I$15 -> 0.225 | P19: =N19+$J$15 -> 0.25 | Q19: =N19+$K$15 -> 0.275 | R19: =N19+$L$15 -> 0.3
I20: X | J20: X | K20: 4 sem | L20: 2 sem
B21: REPASSE MÉDIO | C21: =AVERAGE(C7:C19) -> 0.38846154 | D21: =AVERAGE(D7:D19) -> 0.39615385 | E21: =AVERAGE(E7:E19) -> 0.43384615 | F21: =AVERAGE(F7:F19) -> 0.46153846 | N21: =AVERAGE(N7:N19) -> 0.38846154 | O21: =AVERAGE(O7:O19) -> 0.41346154 | P21: =AVERAGE(P7:P19) -> 0.43846154 | Q21: =AVERAGE(Q7:Q19) -> 0.46346154 | R21: =AVERAGE(R7:R19) -> 0.48846154
O22: =O21-C21 -> 0.025 | P22: =P21-D21 -> 0.042307692 | Q22: =Q21-E21 -> 0.029615385 | R22: =R21-F21 -> 0.026923077

Sheet Indicadores
A1: equipe | B1: id_assessor | C1: nome_assessor | D1: net (atual) | E1: cluster | F1: faixa | G1: cap_1sem | H1: cap_2sem | I1: rec_1sem | J1: rec_2sem | K1: tempo_de_casa | M1: check tempo de casa (anos) | N1: NET médio p/ Assessor | O1: =SUM(D5:D35)/31 -> 43848032 | P1: Retirados os 3 maiores NETs e os 3 menores.
A2: SMART-Unique | B2: =_xlfn.XLOOKUP(C2,POSITIVADOR!B:B,POSITIVADOR!A:A) -> A94378 | C2: Henrique Marengo Teixeira | D2: 257811.07 | E2: {=_xlfn.IFS( D2<=50000000, "Até 50MM", D2<=100000000, "50MM - 100MM", D2<=300000000, "100MM - 300MM", TRUE, "> 300MM" )} -> Até 50MM | F2: {=_xlfn.IFS( D2<=50000000, "GROWING", D2<=100000000, "PLENO", D2<=300000000, "SENIOR", TRUE, "MASTER" )} -> GROWING | G2: 0 | H2: 0 | I2: 0 | J2: 266.3614 | K2: 0 anos, 10 meses e 10 dias | M2: 0 | N2: REC média p/ Assessor (ano) | O2: =SUM(plano_carreira_2026[[#Totals],[rec_1sem]:[rec_2sem]])/37 -> 411407.01
A3: RIO PRETO | B3: =_xlfn.XLOOKUP(C3,POSITIVADOR!B:B,POSITIVADOR!A:A) -> A92776 | C3: Dienifer Natieli Lopes | D3: 8167387.2 | E3: {=_xlfn.IFS( D3<=50000000, "Até 50MM", D3<=100000000, "50MM - 100MM", D3<=300000000, "100MM - 300MM", TRUE, "> 300MM" )} -> Até 50MM | F3: {=_xlfn.IFS( D3<=50000000, "GROWING", D3<=100000000, "PLENO", D3<=300000000, "SENIOR", TRUE, "MASTER" )} -> GROWING | G3: 0 | H3: -616545.61 | I3: 0 | J3: 28803.874 | K3: 1 anos, 2 meses e 16 dias | M3: 7 | N3: CAP média p/ Assessor (ano) | O3: =SUM(plano_carreira_2026[[#Totals],[cap_1sem]:[cap_2sem]])/37 -> -1910155.3
A4: BRAVO | B4: =_xlfn.XLOOKUP(C4,POSITIVADOR!B:B,POSITIVADOR!A:A) -> A28214 | C4: Thiago Budni | D4: 8887785.5 | E4: {=_xlfn.IFS( D4<=50000000, "Até 50MM", D4<=100000000, "50MM - 100MM", D4<=300000000, "100MM - 300MM", TRUE, "> 300MM" )} -> Até 50MM | F4: {=_xlfn.IFS( D4<=50000000, "GROWING", D4<=100000000, "PLENO", D4<=300000000, "SENIOR", TRUE, "MASTER" )} -> GROWING | G4: -426864.22 | H4: -1489156.2 | I4: 48593.588 | J4: 22260.389 | K4: 1 anos, 8 meses e 6 dias | M4: 1 | N4: Tempo médio de casa (ano) | O4: =SUM(M2:M38)/37 -> 2.0810811
A5: RIO PRETO | B5: =_xlfn.XLOOKUP(C5,POSITIVADOR!B:B,POSITIVADOR!A:A) -> A43705 | C5: Cristiane Mellote | D5: 14281693 | E5: {=_xlfn.IFS( D5<=50000000, "Até 50MM", D5<=100000000, "50MM - 100MM", D5<=300000000, "100MM - 300MM", TRUE, "> 300MM" )} -> Até 50MM | F5: {=_xlfn.IFS( D5<=50000000, "GROWING", D5<=100000000, "PLENO", D5<=300000000, "SENIOR", TRUE, "MASTER" )} -> GROWING | G5: 1504061.6 | H5: 1170307.9 | I5: 165782.39 | J5: 109717.19 | K5: 2 anos, 3 meses e 11 dias | M5: 3
A6: SMART-Unique | B6: =_xlfn.XLOOKUP(C6,POSITIVADOR!B:B,POSITIVADOR!A:A) -> A59119 | C6: Rodrigo Conforti | D6: 15725195 | E6: {=_xlfn.IFS( D6<=50000000, "Até 50MM", D6<=100000000, "50MM - 100MM", D6<=300000000, "100MM - 300MM", TRUE, "> 300MM" )} -> Até 50MM | F6: {=_xlfn.IFS( D6<=50000000, "GROWING", D6<=100000000, "PLENO", D6<=300000000, "SENIOR", TRUE, "MASTER" )} -> GROWING | G6: 3658572.1 | H6: 66503.227 | I6: 16511.856 | J6: 47192.53 | K6: 1 anos, 2 meses e 16 dias | M6: 4
A7: PRIVATE | B7: =_xlfn.XLOOKUP(C7,POSITIVADOR!B:B,POSITIVADOR!A:A) -> Private25 | C7: Rodrigo de Sé | D7: 16787310 | E7: {=_xlfn.IFS( D7<=50000000, "Até 50MM", D7<=100000000, "50MM - 100MM", D7<=300000000, "100MM - 300MM", TRUE, "> 300MM" )} -> Até 50MM | F7: {=_xlfn.IFS( D7<=50000000, "GROWING", D7<=100000000, "PLENO", D7<=300000000, "SENIOR", TRUE, "MASTER" )} -> GROWING | G7: 0 | H7: 0 | I7: 0 | J7: 1831.1789 | K7: 0 | M7: 2
A8: BRAVO | B8: =_xlfn.XLOOKUP(C8,POSITIVADOR!B:B,POSITIVADOR!A:A) -> A24356 | C8: Giordano Molinari | D8: 16992210 | E8: {=_xlfn.IFS( D8<=50000000, "Até 50MM", D8<=100000000, "50MM - 100MM", D8<=300000000, "100MM - 300MM", TRUE, "> 300MM" )} -> Até 50MM | F8: {=_xlfn.IFS( D8<=50000000, "GROWING", D8<=100000000, "PLENO", D8<=300000000, "SENIOR", TRUE, "MASTER" )} -> GROWING | G8: 0 | H8: 10924917 | I8: 0 | J8: 1747.6902 | K8: 0 anos, 3 meses e 14 dias | M8: 2
A9: SMART-Unique | B9: =_xlfn.XLOOKUP(C9,POSITIVADOR!B:B,POSITIVADOR!A:A) -> A73778 | C9: Henrique Piragibe | D9: 17728223 | E9: {=_xlfn.IFS( D9<=50000000, "Até 50MM", D9<=100000000, "50MM - 100MM", D9<=300000000, "100MM - 300MM", TRUE, "> 300MM" )} -> Até 50MM | F9: {=_xlfn.IFS( D9<=50000000, "GROWING", D9<=100000000, "PLENO", D9<=300000000, "SENIOR", TRUE, "MASTER" )} -> GROWING | G9: -5237020.6 | H9: -2985197.8 | I9: 64860.716 | J9: 69572.553 | K9: 2 anos, 1 meses e 2 dias | M9: 1
A10: BRAVO | B10: =_xlfn.XLOOKUP(C10,POSITIVADOR!B:B,POSITIVADOR!A:A) -> A73259 | C10: Leandro de Luna | D10: 18246536 | E10: {=_xlfn.IFS( D10<=50000000, "Até 50MM", D10<=100000000, "50MM - 100MM", D10<=300000000, "100MM - 300MM", TRUE, "> 300MM" )} -> Até 50MM | F10: {=_xlfn.IFS( D10<=50000000, "GROWING", D10<=100000000, "PLENO", D10<=300000000, "SENIOR", TRUE, "MASTER" )} -> GROWING | G10: 503204.96 | H10: 827140.6 | I10: 28500.247 | J10: 114076.53 | K10: 0 anos, 5 meses e 21 dias | M10: 1
A11: BRAVO | B11: =_xlfn.XLOOKUP(C11,POSITIVADOR!B:B,POSITIVADOR!A:A) -> A27823 | C11: Diogo Reinoso | D11: 19161669 | E11: {=_xlfn.IFS( D11<=50000000, "Até 50MM", D11<=100000000, "50MM - 100MM", D11<=300000000, "100MM - 300MM", TRUE, "> 300MM" )} -> Até 50MM | F11: {=_xlfn.IFS( D11<=50000000, "GROWING", D11<=100000000, "PLENO", D11<=300000000, "SENIOR", TRUE, "MASTER" )} -> GROWING | G11: -5883661 | H11: 2438812.4 | I11: 27305.157 | J11: 11339.629 | K11: 1 anos, 6 meses e 11 dias | M11: 4
A12: SMART-Global | B12: =_xlfn.XLOOKUP(C12,POSITIVADOR!B:B,POSITIVADOR!A:A) -> A92716 | C12: Rafael Damasceno | D12: 21214016 | E12: {=_xlfn.IFS( D12<=50000000, "Até 50MM", D12<=100000000, "50MM - 100MM", D12<=300000000, "100MM - 300MM", TRUE, "> 300MM" )} -> Até 50MM | F12: {=_xlfn.IFS( D12<=50000000, "GROWING", D12<=100000000, "PLENO", D12<=300000000, "SENIOR", TRUE, "MASTER" )} -> GROWING | G12: 0 | H12: -798235.4 | I12: 0 | J12: 12324.154 | K12: 1 anos, 8 meses e 13 dias | M12: 1
A13: SMART-Assessoria | B13: =_xlfn.XLOOKUP(C13,POSITIVADOR!B:B,POSITIVADOR!A:A) -> A54062 | C13: Luan Prado | D13: 21460036 | E13: {=_xlfn.IFS( D13<=50000000, "Até 50MM", D13<=100000000, "50MM - 100MM", D13<=300000000, "100MM - 300MM", TRUE, "> 300MM" )} -> Até 50MM | F13: {=_xlfn.IFS( D13<=50000000, "GROWING", D13<=100000000, "PLENO", D13<=300000000, "SENIOR", TRUE, "MASTER" )} -> GROWING | G13: 0 | H13: -928212 | I13: 0 | J13: 92877.897 | K13: 1 anos, 0 meses e 0 dias | M13: 1
A14: RIO PRETO | B14: =_xlfn.XLOOKUP(C14,POSITIVADOR!B:B,POSITIVADOR!A:A) -> A72555 | C14: Viviane Fabbri | D14: 22180390 | E14: {=_xlfn.IFS( D14<=50000000, "Até 50MM", D14<=100000000, "50MM - 100MM", D14<=300000000, "100MM - 300MM", TRUE, "> 300MM" )} -> Até 50MM | F14: {=_xlfn.IFS( D14<=50000000, "GROWING", D14<=100000000, "PLENO", D14<=300000000, "SENIOR", TRUE, "MASTER" )} -> GROWING | G14: 889521.26 | H14: 1698546.2 | I14: 132607.57 | J14: 194203.64 | K14: 4 anos, 7 meses e 5 dias | M14: 3
A15: SMART-Unique | B15: =_xlfn.XLOOKUP(C15,POSITIVADOR!B:B,POSITIVADOR!A:A) -> DM 14 | C15: Fabrício Mastro | D15: 22555248 | E15: {=_xlfn.IFS( D15<=50000000, "Até 50MM", D15<=100000000, "50MM - 100MM", D15<=300000000, "100MM - 300MM", TRUE, "> 300MM" )} -> Até 50MM | F15: {=_xlfn.IFS( D15<=50000000, "GROWING", D15<=100000000, "PLENO", D15<=300000000, "SENIOR", TRUE, "MASTER" )} -> GROWING | G15: 0 | H15: -807270.76 | I15: 0 | J15: 26919.186 | K15: 0 anos, 11 meses e 3 dias | M15: 0
A16: SMART-Unique | B16: =_xlfn.XLOOKUP(C16,POSITIVADOR!B:B,POSITIVADOR!A:A) -> A53727 | C16: Rafaela Auslenter | D16: 26660169 | E16: {=_xlfn.IFS( D16<=50000000, "Até 50MM", D16<=100000000, "50MM - 100MM", D16<=300000000, "100MM - 300MM", TRUE, "> 300MM" )} -> Até 50MM | F16: {=_xlfn.IFS( D16<=50000000, "GROWING", D16<=100000000, "PLENO", D16<=300000000, "SENIOR", TRUE, "MASTER" )} -> GROWING | G16: -1979223.1 | H16: -2354930.5 | I16: 163825.97 | J16: 178610.08 | K16: 1 anos, 8 meses e 13 dias | M16: 4
A17: RIO PRETO | B17: =_xlfn.XLOOKUP(C17,POSITIVADOR!B:B,POSITIVADOR!A:A) -> A56706 | C17: Evandro Delduque | D17: 27456073 | E17: {=_xlfn.IFS( D17<=50000000, "Até 50MM", D17<=100000000, "50MM - 100MM", D17<=300000000, "100MM - 300MM", TRUE, "> 300MM" )} -> Até 50MM | F17: {=_xlfn.IFS( D17<=50000000, "GROWING", D17<=100000000, "PLENO", D17<=300000000, "SENIOR", TRUE, "MASTER" )} -> GROWING | G17: 12557461 | H17: 7538418.4 | I17: 135299.78 | J17: 137823.18 | K17: 1 anos, 3 meses e 21 dias | M17: 1
A18: SMART-Assessoria | B18: =_xlfn.XLOOKUP(C18,POSITIVADOR!B:B,POSITIVADOR!A:A) -> A46046 | C18: Leonardo Dantas | D18: 27725249 | E18: {=_xlfn.IFS( D18<=50000000, "Até 50MM", D18<=100000000, "50MM - 100MM", D18<=300000000, "100MM - 300MM", TRUE, "> 300MM" )} -> Até 50MM | F18: {=_xlfn.IFS( D18<=50000000, "GROWING", D18<=100000000, "PLENO", D18<=300000000, "SENIOR", TRUE, "MASTER" )} -> GROWING | G18: -7663419.2 | H18: -3911417.2 | I18: 137577.52 | J18: 155026.03 | K18: 1 anos, 6 meses e 26 dias | M18: 0
A19: SMART-Assessoria | B19: =_xlfn.XLOOKUP(C19,POSITIVADOR!B:B,POSITIVADOR!A:A) -> A47207 | C19: João Teixeira | D19: 30803534 | E19: {=_xlfn.IFS( D19<=50000000, "Até 50MM", D19<=100000000, "50MM - 100MM", D19<=300000000, "100MM - 300MM", TRUE, "> 300MM" )} -> Até 50MM | F19: {=_xlfn.IFS( D19<=50000000, "GROWING", D19<=100000000, "PLENO", D19<=300000000, "SENIOR", TRUE, "MASTER" )} -> GROWING | G19: -10508874 | H19: -6032749.6 | I19: 207175.12 | J19: 225973.61 | K19: 2 anos, 1 meses e 14 dias | M19: 0
... A38: PRIVATE | B38: =_xlfn.XLOOKUP(C38,POSITIVADOR!B:B,POSITIVADOR!A:A) -> A21351 | C38: Alexandre França | D38: 2.5668798e+08 | E38: {=_xlfn.IFS( D38<=50000000, "Até 50MM", D38<=100000000, "50MM - 100MM", D38<=300000000, "100MM - 300MM", TRUE, "> 300MM" )} -> 100MM - 300MM | F38: {=_xlfn.IFS( D38<=50000000, "GROWING", D38<=100000000, "PLENO", D38<=300000000, "SENIOR", TRUE, "MASTER" )} -> SENIOR | G38: -5858023.2 | H38: 39130100 | I38: 519381.93 | J38: 639470.96 | K38: 7 anos, 0 meses e 19 dias | M38: 4
D39: =SUBTOTAL(109,plano_carreira_2026[net (atual)]) -> 2.0170522e+09 | G39: =SUBTOTAL(109,plano_carreira_2026[cap_1sem]) -> -84278013 | H39: =SUBTOTAL(109,plano_carreira_2026[cap_2sem]) -> 13602268 | I39: =SUM(plano_carreira_2026[rec_1sem]) -> 6637039.3 | J39: =SUBTOTAL(109,plano_carreira_2026[rec_2sem]) -> 8585020.1 | M39: =SUM(M2:M38) -> 77

Sheet tempo de casa
A1: Nome Completo | B1: Entrada Nobel | C1: Hoje | D1: Tempo de Casa (ano) | E1: Tempo de casa (completo)
A2: Adriano Fonseca | B2: 45846 | C2: =TODAY() -> 46049 | D2: =DATEDIF(B2, C2, "Y") -> 0 | E2: =DATEDIF(B2,C2,"Y") & " anos, " & DATEDIF(B2,C2,"YM") & " meses e " & DATEDIF(B2,C2,"MD") & " dias" -> 0 anos, 6 meses e 19 dias | J2: A65954 | K2: Adriano Fonseca
A3: Alexandre França | B3: 43466 | C3: =TODAY() -> 46049 | D3: =DATEDIF(B3, C3, "Y") -> 7 | E3: =DATEDIF(B3,C3,"Y") & " anos, " & DATEDIF(B3,C3,"YM") & " meses e " & DATEDIF(B3,C3,"MD") & " dias" -> 7 anos, 0 meses e 26 dias | J3: A21351 | K3: Alexandre França
A4: Alvaro Villa | B4: 45670 | C4: =TODAY() -> 46049 | D4: =DATEDIF(B4, C4, "Y") -> 1 | E4: =DATEDIF(B4,C4,"Y") & " anos, " & DATEDIF(B4,C4,"YM") & " meses e " & DATEDIF(B4,C4,"MD") & " dias" -> 1 anos, 0 meses e 14 dias | J4: A65997 | K4: Alvaro Villa
A5: Nina Lima | B5: 44621 | C5: =TODAY() -> 46049 | D5: =DATEDIF(B5, C5, "Y") -> 3 | E5: =DATEDIF(B5,C5,"Y") & " anos, " & DATEDIF(B5,C5,"YM") & " meses e " & DATEDIF(B5,C5,"MD") & " dias" -> 3 anos, 10 meses e 26 dias | J5: A26112 | K5: Argos Urbano
A6: Argos Urbano | B6: 44858 | C6: =TODAY() -> 46049 | D6: =DATEDIF(B6, C6, "Y") -> 3 | E6: =DATEDIF(B6,C6,"Y") & " anos, " & DATEDIF(B6,C6,"YM") & " meses e " & DATEDIF(B6,C6,"MD") & " dias" -> 3 anos, 3 meses e 3 dias | J6: A26562 | K6: Caio Marques
A7: Bárbara Miura | B7: 46023 | C7: =TODAY() -> 46049 | D7: =DATEDIF(B7, C7, "Y") -> 0 | E7: =DATEDIF(B7,C7,"Y") & " anos, " & DATEDIF(B7,C7,"YM") & " meses e " & DATEDIF(B7,C7,"MD") & " dias" -> 0 anos, 0 meses e 26 dias | J7: A43705 | K7: Cristiane Mellote
A8: Caio Marques | B8: 44562 | C8: =TODAY() -> 46049 | D8: =DATEDIF(B8, C8, "Y") -> 4 | E8: =DATEDIF(B8,C8,"Y") & " anos, " & DATEDIF(B8,C8,"YM") & " meses e " & DATEDIF(B8,C8,"MD") & " dias" -> 4 anos, 0 meses e 26 dias | J8: A53211 | K8: Diana Frajtag
A9: Cristiane Mellote | B9: 45208 | C9: =TODAY() -> 46049 | D9: =DATEDIF(B9, C9, "Y") -> 2 | E9: =DATEDIF(B9,C9,"Y") & " anos, " & DATEDIF(B9,C9,"YM") & " meses e " & DATEDIF(B9,C9,"MD") & " dias" -> 2 anos, 3 meses e 18 dias | J9: A92776 | K9: Dienifer Natieli Lopes
A10: Diana Frajtag | B10: 44963 | C10: =TODAY() -> 46049 | D10: =DATEDIF(B10, C10, "Y") -> 2 | E10: =DATEDIF(B10,C10,"Y") & " anos, " & DATEDIF(B10,C10,"YM") & " meses e " & DATEDIF(B10,C10,"MD") & " dias" -> 2 anos, 11 meses e 21 dias | J10: A27823 | K10: Diogo Reinoso
A11: Dienifer Natieli Lopes | B11: 45600 | C11: =TODAY() -> 46049 | D11: =DATEDIF(B11, C11, "Y") -> 1 | E11: =DATEDIF(B11,C11,"Y") & " anos, " & DATEDIF(B11,C11,"YM") & " meses e " & DATEDIF(B11,C11,"MD") & " dias" -> 1 anos, 2 meses e 23 dias | J11: A72984 | K11: Elise Okayama
A12: Diogo Reinoso | B12: 45482 | C12: =TODAY() -> 46049 | D12: =DATEDIF(B12, C12, "Y") -> 1 | E12: =DATEDIF(B12,C12,"Y") & " anos, " & DATEDIF(B12,C12,"YM") & " meses e " & DATEDIF(B12,C12,"MD") & " dias" -> 1 anos, 6 meses e 18 dias | J12: A56706 | K12: Evandro Delduque
A13: Elise Okayama | B13: 44348 | C13: =TODAY() -> 46049 | D13: =DATEDIF(B13, C13, "Y") -> 4 | E13: =DATEDIF(B13,C13,"Y") & " anos, " & DATEDIF(B13,C13,"YM") & " meses e " & DATEDIF(B13,C13,"MD") & " dias" -> 4 anos, 7 meses e 26 dias | J13: A22679 | K13: Fabio Galdino
... A39: Viviane Fabbri | B39: 44362 | C39: =TODAY() -> 46049 | D39: =DATEDIF(B39, C39, "Y") -> 4 | E39: =DATEDIF(B39,C39,"Y") & " anos, " & DATEDIF(B39,C39,"YM") & " meses e " & DATEDIF(B39,C39,"MD") & " dias" -> 4 anos, 7 meses e 12 dias | J39: A48396 | K39: Tiago Londres
A40: Rodrigo de Sé | J40: A72555 | K40: Viviane Fabbri

Sheet captacao_1sem
A1: Cód. Assessor | B1: Nome Assessor | C1: Núcleo | D1: Capitação Líquida | E1: Período
A2: A20345 | B2: Luis Valente | C2: PRIVATE | D2: 33183.631 | E2: 45658
A3: A20841 | B3: Walter Fogolin | C3: PRIVATE | D3: -52.98 | E3: 45658
A4: A21007 | B4: Paulo Wu Dirickson | C4: RIO DE JANEIRO | D4: 1396431 | E4: 45658
A5: A21351 | B5: Alexandre França | C5: PRIVATE | D5: -2092748.6 | E5: 45658
A6: A21773 | B6: Lourdes Marretto | C6: SÃO JOSÉ | D6: 44471.71 | E6: 45658
A7: A21878 | B7: Roberta Figueira | C7: BETA | D7: -3491503.4 | E7: 45658
A8: A22679 | B8: Fabio Galdino | C8: BETA | D8: -583479.3 | E8: 45658
A9: A24984 | B9: Leandro Barbancho | C9: BETA | D9: -5468651.1 | E9: 45658
A10: A25771 | B10: Luis Vieira | C10: PRIVATE | D10: 56560.96 | E10: 45658
A11: A26112 | B11: Argos Urbano | C11: ATENA | D11: 296455.47 | E11: 45658
A12: A26562 | B12: Caio Marques | C12: DELTA | D12: -4747082.4 | E12: 45658
A13: A26852 | B13: Lucas Pradella | C13: CHARLIE | D13: 885332.19 | E13: 45658
... A295: RJ 01 | B295: Nathalia Ribeiro | C295: RIO DE JANEIRO | D295: -6731592.2 | E295: 45809

Sheet captacao_2sem
A1: id_assessor | B1: Nome Assessor | C1: Núcleo | D1: Capitação Líquida | E1: Período
A2: A21351 | B2: Alexandre França | C2: PRIVATE | D2: 40207918 | E2: 45839
A3: A21399 | B3: João Carlos | C3: PRIVATE | D3: 234197.02 | E3: 45839
A4: A21878 | B4: Roberta Figueira | C4: BETA | D4: -6695814.8 | E4: 45839
A5: A22679 | B5: Fabio Galdino | C5: BETA | D5: 1396605.7 | E5: 45839
A6: A24984 | B6: Leandro Barbancho | C6: BETA | D6: -466338.34 | E6: 45839
A7: A25771 | B7: Luis Vieira | C7: PRIVATE | D7: -237950.16 | E7: 45839
A8: A26112 | B8: Argos Urbano | C8: ATENA | D8: 2497506.5 | E8: 45839
A9: A26562 | B9: Caio Marques | C9: DELTA | D9: 444218.41 | E9: 45839
A10: A26852 | B10: Lucas Pradella | C10: CHARLIE | D10: 74658.782 | E10: 45839
A11: A26918 | B11: Nina Lima | C11: CHARLIE | D11: -331810.96 | E11: 45839
A12: A27823 | B12: Diogo Reinoso | C12: SÃO JOSÉ | D12: 64730.826 | E12: 45839
A13: A27942 | B13: #N/D | C13: #N/D | D13: -9381.62 | E13: 45839
... A279: FINDER01 | B279: GEOVANNA FINDER | C279: SMART-Global | D279: -100 | E279: 45992

Sheet receita_1sem
A1: Id_Assessor | B1: Assessor | C1: Núcleo | D1: Período | E1: sum(grp.receita) | F1: Média de Receita | G1: Média Receita AUM(até periodo) | H1: roa | I1: Roa Anualizado
A2: A51250 | B2: A51250 | C2: SMART | D2: 01/2025 | E2: 207.7254 | F2: 207.7254 | G2: 2313507.9 | H2: 8.9788067e-05 | I2: 0.0010774568
A3: A43562 | B3: Adriano Mitidiero | C3: CHARLIE | D3: 01/2025 | E3: 10591.724 | F3: 10591.724 | G3: 7054791.3 | H3: 0.0015013519 | I3: 0.018016222
A4: A21351 | B4: Alexandre França | C4: PRIVATE | D4: 01/2025 | E4: 54676.448 | F4: 54676.448 | G4: 2.0410902e+08 | H4: 0.00026787864 | I4: 0.0032145437
A5: A65997 | B5: Alvaro Villa | C5: PRIVATE | D5: 01/2025 | E5: 462.1687 | F5: 462.1687 | G5: 14057871 | H5: 3.2876153e-05 | I5: 0.00039451383
A6: A26112 | B6: Argos Urbano | C6: CAMPINAS | D6: 01/2025 | E6: 17295.487 | F6: 17295.487 | G6: 47954631 | H6: 0.00036066354 | I6: 0.0043279624
A7: A26562 | B7: Caio Marques | C7: CHARLIE | D7: 01/2025 | E7: 15909.595 | F7: 15909.595 | G7: 51752216 | H7: 0.00030741862 | I7: 0.0036890235
A8: A43958 | B8: Caio Mitidiero | C8: RIO PRETO | D8: 01/2025 | E8: 749.6653 | F8: 749.6653 | G8: 48729.78 | H8: 0.015384131 | I8: 0.18460957
A9: A43705 | B9: Cristiane Mellote | C9: RIO PRETO | D9: 01/2025 | E9: 49581.813 | F9: 49581.813 | G9: 8332155.4 | H9: 0.0059506588 | I9: 0.071407905
A10: A53211 | B10: Diana Frajtag | C10: RIO DE JANEIRO | D10: 01/2025 | E10: 11716.965 | F10: 11716.965 | G10: 55759640 | H10: 0.00021013345 | I10: 0.0025216014
A11: A27823 | B11: Diogo Reinoso | C11: RIO DE JANEIRO | D11: 01/2025 | E11: 21396.141 | F11: 21396.141 | G11: 12911032 | H11: 0.0016571983 | I11: 0.01988638
A12: DM 10 | B12: DM 10 | C12: SMART | D12: 01/2025 | E12: 804.9971 | F12: 804.9971 | G12: 87468.144 | H12: 0.0092033174 | I12: 0.11043981
A13: A72984 | B13: Elise Okayama | C13: RIO PRETO | D13: 01/2025 | E13: 41060.137 | F13: 41060.137 | G13: 82832957 | H13: 0.00049569807 | I13: 0.0059483769
... A289: A73859 | B289: Walter Alves | C289: CHARLIE | D289: 06/2025 | E289: 1.1788 | F289: 1.1788 | G289: 131.43545 | H289: 0 | I289: 0

Sheet receita_2sem
A1: Id_Assessor | B1: Assessor | C1: Núcleo | D1: Período | E1: sum(grp.receita) | F1: Média de Receita | G1: Média Receita AUM(até periodo) | H1: roa | I1: Roa Anualizado
A2: A51250 | B2: A51250 | C2: SMART | D2: 07/2025 | E2: 531.8382 | F2: 531.8382 | G2: 25045.737 | H2: 0.00021234679 | I2: 0.0025481615
A3: PRIVATE01 | B3: Adriano Fonseca | C3: PRIVATE | D3: 07/2025 | E3: 120038.36 | F3: 120038.36 | G3: 1645803.6 | H3: 0.00072936015 | I3: 0.0087523219
A4: A43562 | B4: Adriano Mitidiero | C4: CHARLIE | D4: 07/2025 | E4: 4491.473 | F4: 4491.473 | G4: 94618.063 | H4: 0.00047469509 | I4: 0.0056963411
A5: A21351 | B5: Alexandre França | C5: PRIVATE | D5: 07/2025 | E5: 115441.51 | F5: 115441.51 | G5: 2611322.4 | H5: 0.00044208066 | I5: 0.0053049679
A6: A65997 | B6: Alvaro Villa | C6: PRIVATE | D6: 07/2025 | E6: 170042.99 | F6: 170042.99 | G6: 441556.24 | H6: 0.0038509929 | I6: 0.046211915
A7: A26112 | B7: Argos Urbano | C7: SÃO JOSÉ | D7: 07/2025 | E7: 27104.804 | F7: 27104.804 | G7: 592261.35 | H7: 0.00045764939 | I7: 0.0054917926
A8: A26562 | B8: Caio Marques | C8: CHARLIE | D8: 07/2025 | E8: 23539.173 | F8: 23539.173 | G8: 595013.42 | H8: 0.00039560744 | I8: 0.0047472892
A9: A43705 | B9: Cristiane Mellote | C9: RIO PRETO | D9: 07/2025 | E9: 17884.498 | F9: 17884.498 | G9: 107603.33 | H9: 0.0016620766 | I9: 0.019944919
A10: A53211 | B10: Diana Frajtag | C10: SÃO JOSÉ | D10: 07/2025 | E10: 18143.642 | F10: 18143.642 | G10: 570077.88 | H10: 0.00031826603 | I10: 0.0038191924
A11: A27823 | B11: Diogo Reinoso | C11: RIO PRETO | D11: 07/2025 | E11: 1404.0079 | F11: 1404.0079 | G11: 157803.78 | H11: 8.8971753e-05 | I11: 0.001067661
A12: DM 14 | B12: DM 14 | C12: SMART | D12: 07/2025 | E12: 3099.1128 | F12: 3099.1128 | G12: 141434.17 | H12: 0.00021912051 | I12: 0.0026294461
A13: A72984 | B13: Elise Okayama | C13: RIO PRETO | D13: 07/2025 | E13: 40965.818 | F13: 40965.818 | G13: 822597.36 | H13: 0.00049800571 | I13: 0.0059760685
... A273: A72555 | B273: Viviane Fabbri | C273: RIO PRETO | D273: 12/2025 | E273: 15286.282 | F273: 15286.282 | G273: 220884.19 | H273: 0.00069204962 | I273: 0.0083045955

Sheet captacao_total_2025
A1: id_assessor | B1: Nome Assessor | C1: Núcleo | D1: Capitação Líquida | E1: Período
A2: A20345 | B2: Luis Valente | C2: PRIVATE | D2: 33183.631 | E2: 45658
A3: A20841 | B3: Walter Fogolin | C3: PRIVATE | D3: -52.98 | E3: 45658
A4: A21007 | B4: Paulo Wu Dirickson | C4: RIO DE JANEIRO | D4: 1396431 | E4: 45658
A5: A21351 | B5: Alexandre França | C5: PRIVATE | D5: -2092748.6 | E5: 45658
A6: A21773 | B6: Lourdes Marretto | C6: SÃO JOSÉ | D6: 44471.71 | E6: 45658
A7: A21878 | B7: Roberta Figueira | C7: BETA | D7: -3491503.4 | E7: 45658
A8: A22679 | B8: Fabio Galdino | C8: BETA | D8: -583479.3 | E8: 45658
A9: A24984 | B9: Leandro Barbancho | C9: BETA | D9: -5468651.1 | E9: 45658
A10: A25771 | B10: Luis Vieira | C10: PRIVATE | D10: 56560.96 | E10: 45658
A11: A26112 | B11: Argos Urbano | C11: ATENA | D11: 296455.47 | E11: 45658
A12: A26562 | B12: Caio Marques | C12: DELTA | D12: -4747082.4 | E12: 45658
A13: A26852 | B13: Lucas Pradella | C13: CHARLIE | D13: 885332.19 | E13: 45658
... A573: FINDER01 | B573: GEOVANNA FINDER | C573: SMART-Global | D573: -100 | E573: 45992

Sheet receita_total_2025
A1: Id_Assessor | B1: Assessor | C1: Núcleo | D1: Período | E1: sum(grp.receita) | F1: Média de Receita | G1: Média Receita AUM(até periodo) | H1: roa | I1: Roa Anualizado
A2: A51250 | B2: A51250 | C2: SMART | D2: 01/2025 | E2: 207.7254 | F2: 207.7254 | G2: 2313507.9 | H2: 8.9788067e-05 | I2: 0.0010774568
A3: A43562 | B3: Adriano Mitidiero | C3: CHARLIE | D3: 01/2025 | E3: 10591.724 | F3: 10591.724 | G3: 7054791.3 | H3: 0.0015013519 | I3: 0.018016222
A4: A21351 | B4: Alexandre França | C4: PRIVATE | D4: 01/2025 | E4: 54676.448 | F4: 54676.448 | G4: 2.0410902e+08 | H4: 0.00026787864 | I4: 0.0032145437
A5: A65997 | B5: Alvaro Villa | C5: PRIVATE | D5: 01/2025 | E5: 462.1687 | F5: 462.1687 | G5: 14057871 | H5: 3.2876153e-05 | I5: 0.00039451383
A6: A26112 | B6: Argos Urbano | C6: CAMPINAS | D6: 01/2025 | E6: 17295.487 | F6: 17295.487 | G6: 47954631 | H6: 0.00036066354 | I6: 0.0043279624
A7: A26562 | B7: Caio Marques | C7: CHARLIE | D7: 01/2025 | E7: 15909.595 | F7: 15909.595 | G7: 51752216 | H7: 0.00030741862 | I7: 0.0036890235
A8: A43958 | B8: Caio Mitidiero | C8: RIO PRETO | D8: 01/2025 | E8: 749.6653 | F8: 749.6653 | G8: 48729.78 | H8: 0.015384131 | I8: 0.18460957
A9: A43705 | B9: Cristiane Mellote | C9: RIO PRETO | D9: 01/2025 | E9: 49581.813 | F9: 49581.813 | G9: 8332155.4 | H9: 0.0059506588 | I9: 0.071407905
A10: A53211 | B10: Diana Frajtag | C10: RIO DE JANEIRO | D10: 01/2025 | E10: 11716.965 | F10: 11716.965 | G10: 55759640 | H10: 0.00021013345 | I10: 0.0025216014
A11: A27823 | B11: Diogo Reinoso | C11: RIO DE JANEIRO | D11: 01/2025 | E11: 21396.141 | F11: 21396.141 | G11: 12911032 | H11: 0.0016571983 | I11: 0.01988638
A12: DM 10 | B12: DM 10 | C12: SMART | D12: 01/2025 | E12: 804.9971 | F12: 804.9971 | G12: 87468.144 | H12: 0.0092033174 | I12: 0.11043981
A13: A72984 | B13: Elise Okayama | C13: RIO PRETO | D13: 01/2025 | E13: 41060.137 | F13: 41060.137 | G13: 82832957 | H13: 0.00049569807 | I13: 0.0059483769
... A561: A72555 | B561: Viviane Fabbri | C561: RIO PRETO | D561: 12/2025 | E561: 15286.282 | F561: 15286.282 | G561: 220884.19 | H561: 0.00069204962 | I561: 0.0083045955

Sheet Planilha2
A1: Id_Assessor | B1: Assessor | C1: Núcleo | D1: Período | E1: sum(grp.receita)
A2: A51250 | B2: A51250 | C2: SMART-Global | D2: 10/2025 | E2: 3847.3698
A3: A65954 | B3: Adriano Fonseca | C3: PRIVATE | D3: 10/2025 | E3: 121966.4
A4: A43562 | B4: Adriano Mitidiero | C4: SÃO JOSÉ | D4: 10/2025 | E4: 968.7957
A5: A21351 | B5: Alexandre França | C5: PRIVATE | D5: 10/2025 | E5: 52951.177
A6: A65997 | B6: Alvaro Villa | C6: PRIVATE | D6: 10/2025 | E6: 130266.06
A7: A26112 | B7: Argos Urbano | C7: SÃO JOSÉ | D7: 10/2025 | E7: 25093.967
A8: A26562 | B8: Caio Marques | C8: SÃO JOSÉ | D8: 10/2025 | E8: 23501.986
A9: A43705 | B9: Cristiane Mellote | C9: RIO PRETO | D9: 10/2025 | E9: 8696.8492
A10: A53211 | B10: Diana Frajtag | C10: SÃO JOSÉ | D10: 10/2025 | E10: 11923.506
A11: A92776 | B11: DIENIFER NATIELI LOPES | C11: RIO PRETO | D11: 10/2025 | E11: 2039.8085
A12: A27823 | B12: Diogo Reinoso | C12: SÃO JOSÉ | D12: 10/2025 | E12: 1796.8615
A13: A72984 | B13: Elise Okayama | C13: RIO PRETO | D13: 10/2025 | E13: 180487.08
... A134: A72555 | B134: Viviane Fabbri | C134: RIO PRETO | D134: 12/2025 | E134: 15286.282

Sheet POSITIVADOR
A1: Código Real | B1: Assessor | C1: Núcleo | D1: Cliente | E1: Status | F1: Ativou em M? | G1: Net Em M
A2: DM 14 | B2: Fabrício Mastro | C2: SMART-Unique | D2: 681 | E2: INATIVO | F2: Não | G2: 0
A3: DM 14 | B3: Fabrício Mastro | C3: SMART-Unique | D3: 5481 | E3: INATIVO | F3: Não | G3: 0
A4: A92716 | B4: Rafael Damasceno | C4: SMART-Global | D4: 5667 | E4: ATIVO | F4: Não | G4: 3136.8978
A5: DM 14 | B5: Fabrício Mastro | C5: SMART-Unique | D5: 12647 | E5: ATIVO | F5: Não | G5: 29049.457
A6: DM 14 | B6: Fabrício Mastro | C6: SMART-Unique | D6: 14335 | E6: INATIVO | F6: Não | G6: 0
A7: DM 14 | B7: Fabrício Mastro | C7: SMART-Unique | D7: 14893 | E7: ATIVO | F7: Não | G7: 113.53633
A8: A92716 | B8: Rafael Damasceno | C8: SMART-Global | D8: 14972 | E8: ATIVO | F8: Não | G8: 1.2e-17
A9: A74230 | B9: Felipe Sellan | C9: BRAVO | D9: 15138 | E9: ATIVO | F9: Não | G9: 107636.12
A10: A28214 | B10: Thiago Budni | C10: BRAVO | D10: 15667 | E10: ATIVO | F10: Não | G10: 10124.3
A11: DM 14 | B11: Fabrício Mastro | C11: SMART-Unique | D11: 15808 | E11: INATIVO | F11: Não | G11: 0
A12: A92716 | B12: Rafael Damasceno | C12: SMART-Global | D12: 19222 | E12: ATIVO | F12: Não | G12: 213.76
A13: A26918 | B13: Nina Lima | C13: BRAVO | D13: 19767 | E13: ATIVO | F13: Não | G13: 269586.36
... A1184: A26852 | B1184: Lucas Pradella | C1184: SMART-Unique | D1184: 2954556 | E1184: ATIVO | F1184: Não | G1184: 50612.797
A1185: A53727 | B1185: Rafaela Auslenter | C1185: SMART-Unique | D1185: 2955408 | G1185: 0
A1186: DM 14 | B1186: Fabrício Mastro | C1186: SMART-Unique | D1186: 2956965 | E1186: INATIVO | F1186: Não | G1186: 0
A1187: DM 14 | B1187: Fabrício Mastro | C1187: SMART-Unique | D1187: 2957587 | E1187: INATIVO | F1187: Não | G1187: 0
A1188: DM 14 | B1188: Fabrício Mastro | C1188: SMART-Unique | D1188: 2959142 | E1188: ATIVO | F1188: Não | G1188: 28746.094
A1189: A92716 | B1189: Rafael Damasceno | C1189: SMART-Global | D1189: 2961747 | E1189: INATIVO | F1189: Não | G1189: 0
A1190: DM 14 | B1190: Fabrício Mastro | C1190: SMART-Unique | D1190: 2964064 | E1190: INATIVO | F1190: Não | G1190: 0
A1191: DM 14 | B1191: Fabrício Mastro | C1191: SMART-Unique | D1191: 2964121 | E1191: INATIVO | F1191: Não | G1191: 0
A1192: A53211 | B1192: Diana Frajtag | C1192: BRAVO | D1192: 2965852 | E1192: ATIVO | F1192: Não | G1192: 1373682.1
A1193: A92716 | B1193: Rafael Damasceno | C1193: SMART-Global | D1193: 2966744 | E1193: ATIVO | F1193: Não | G1193: 3269.9138
A1194: DM 14 | B1194: Fabrício Mastro | C1194: SMART-Unique | D1194: 2968745 | E1194: INATIVO | F1194: Não | G1194: 0
A1195: DM 14 | B1195: Fabrício Mastro | C1195: SMART-Unique | D1195: 2972393 | E1195: INATIVO | F1195: Não | G1195: 0
A1196: A21878 | B1196: Roberta Figueira | C1196: PRIVATE | D1196: 2972395 | E1196: ATIVO | F1196: Não | G1196: 1890113.3
A1197: A92716 | B1197: Rafael Damasceno | C1197: SMART-Global | D1197: 2980022 | E1197: ATIVO | F1197: Não | G1197: 372.57
... A1699: A92716 | B1699: Rafael Damasceno | C1699: SMART-Global | D1699: 3741363 | E1699: ATIVO | F1699: Não | G1699: 62963.252
A1700: A73259 | B1700: Leandro de Luna | C1700: BRAVO | D1700: 3741923 | G1700: 0
A1701: A32005 | B1701: Fabio Ribeiro | C1701: BRAVO | D1701: 3743289 | E1701: ATIVO | F1701: Não | G1701: 195587.29
A1702: DM 14 | B1702: Fabrício Mastro | C1702: SMART-Unique | D1702: 3744070 | E1702: INATIVO | F1702: Não | G1702: 0.01
A1703: DM 14 | B1703: Fabrício Mastro | C1703: SMART-Unique | D1703: 3744244 | E1703: INATIVO | F1703: Não | G1703: 0
A1704: DM 14 | B1704: Fabrício Mastro | C1704: SMART-Unique | D1704: 3744349 | E1704: INATIVO | F1704: Não | G1704: 20.24
A1705: DM 14 | B1705: Fabrício Mastro | C1705: SMART-Unique | D1705: 3747563 | E1705: INATIVO | F1705: Não | G1705: 13.24
A1706: A92716 | B1706: Rafael Damasceno | C1706: SMART-Global | D1706: 3748609 | E1706: ATIVO | F1706: Não | G1706: 12134.734
A1707: A21878 | B1707: Roberta Figueira | C1707: PRIVATE | D1707: 3749537 | E1707: ATIVO | F1707: Não | G1707: 245.83
A1708: A73259 | B1708: Leandro de Luna | C1708: BRAVO | D1708: 3750337 | E1708: INATIVO | F1708: Não | G1708: 0
A1709: A74348 | B1709: Simone Augusto | C1709: BRAVO | D1709: 3750721 | E1709: ATIVO | F1709: Não | G1709: 217106.44
A1710: A21399 | B1710: João Carlos | C1710: PRIVATE | D1710: 3751150 | E1710: ATIVO | F1710: Não | G1710: 77164.14
A1711: A26918 | B1711: Nina Lima | C1711: BRAVO | D1711: 3751634 | E1711: ATIVO | F1711: Não | G1711: 408641.65
...

Sheet impacto_financeiro
A1: equipe | B1: id_assessor | C1: nome_assessor | D1: net (atual) | E1: cluster | F1: faixa
A2: SMART-Unique | B2: A94378 | C2: Henrique Marengo Teixeira | D2: 257811.07 | E2: Até 50MM | F2: GROWING
A3: RIO PRETO | B3: A92776 | C3: Dienifer Natieli Lopes | D3: 8167387.2 | E3: Até 50MM | F3: GROWING
A4: BRAVO | B4: A28214 | C4: Thiago Budni | D4: 8887785.5 | E4: Até 50MM | F4: GROWING
A5: RIO PRETO | B5: A43705 | C5: Cristiane Mellote | D5: 14281693 | E5: Até 50MM | F5: GROWING
A6: SMART-Unique | B6: A59119 | C6: Rodrigo Conforti | D6: 15725195 | E6: Até 50MM | F6: GROWING
A7: PRIVATE | B7: Private25 | C7: Rodrigo de Sé | D7: 16787310 | E7: Até 50MM | F7: GROWING
A8: BRAVO | B8: A24356 | C8: Giordano Molinari | D8: 16992210 | E8: Até 50MM | F8: GROWING
A9: SMART-Unique | B9: A73778 | C9: Henrique Piragibe | D9: 17728223 | E9: Até 50MM | F9: GROWING
A10: BRAVO | B10: A73259 | C10: Leandro de Luna | D10: 18246536 | E10: Até 50MM | F10: GROWING
A11: BRAVO | B11: A27823 | C11: Diogo Reinoso | D11: 19161669 | E11: Até 50MM | F11: GROWING
A12: SMART-Global | B12: A92716 | C12: Rafael Damasceno | D12: 21214016 | E12: Até 50MM | F12: GROWING
A13: SMART-Assessoria | B13: A54062 | C13: Luan Prado | D13: 21460036 | E13: Até 50MM | F13: GROWING
... A38: PRIVATE | B38: A21351 | C38: Alexandre França | D38: 2.5668798e+08 | E38: 100MM - 300MM | F38: SENIOR
